<?xml version="1.0" ?>
<robot xmlns:xacro="http://ros.org/wiki/xacro">
  <xacro:macro name="rs005l" params="prefix">

    <!-- Properties -->
    <material name="blue">
      <color rgba="0.5 0.5 0.5 1" />
    </material>
    <material name="white">
      <color rgba="0.95294 0.95294 0.95294 1" />
    </material>

    <!-- link list -->
    <link name="${prefix}base_link">
      <visual>
        <geometry>
          <mesh filename="package://kawasaki/meshes/rs005l/base_link.stl" scale="1000 1000 1000" />
        </geometry>
        <material name="blue"/>
      </visual>
      <collision>
        <geometry>
          <mesh filename="package://kawasaki/meshes/rs005l/base_link.stl" scale="1000 1000 1000" />
        </geometry>
      </collision>
    </link>
    <link name="${prefix}link_1_s">
      <visual>
        <geometry>
          <mesh filename="package://kawasaki/meshes/rs005l/link_1_s.stl" scale="1000 1000 1000" />
        </geometry>
        <material name="blue"/>
      </visual>
      <collision>
        <geometry>
          <mesh filename="package://kawasaki/meshes/rs005l/link_1_s.stl" scale="1000 1000 1000" />
        </geometry>
      </collision>
    </link>
    <link name="${prefix}link_2_l">
      <visual>
        <geometry>
          <mesh filename="package://kawasaki/meshes/rs005l/link_2_l.stl" scale="1000 1000 1000" />
        </geometry>
        <material name="blue"/>
      </visual>
      <collision>
        <geometry>
          <mesh filename="package://kawasaki/meshes/rs005l/link_2_l.stl" scale="1000 1000 1000" />
        </geometry>
      </collision>
    </link>
    <link name="${prefix}link_3_u">
      <visual>
        <geometry>
          <mesh filename="package://kawasaki/meshes/rs005l/link_3_u.stl" scale="1000 1000 1000" />
        </geometry>
        <material name="blue"/>
      </visual>
      <collision>
        <geometry>
          <mesh filename="package://kawasaki/meshes/rs005l/link_3_u.stl" scale="1000 1000 1000" />
        </geometry>
      </collision>
    </link>
    <link name="${prefix}link_4_r">
      <visual>
        <geometry>
          <mesh filename="package://kawasaki/meshes/rs005l/link_4_r.stl" scale="1000 1000 1000" />
        </geometry>
        <material name="blue"/>
      </visual>
      <collision>
        <geometry>
          <mesh filename="package://kawasaki/meshes/rs005l/link_4_r.stl" scale="1000 1000 1000" />
        </geometry>
      </collision>
    </link>
    <link name="${prefix}link_5_b">
      <visual>
        <geometry>
          <mesh filename="package://kawasaki/meshes/rs005l/link_5_b.stl" scale="1000 1000 1000" />
        </geometry>
        <material name="blue"/>
      </visual>
      <collision>
        <geometry>
          <mesh filename="package://kawasaki/meshes/rs005l/link_5_b.stl" scale="1000 1000 1000" />
        </geometry>
      </collision>
    </link>
    <link name="${prefix}link_6_t">
      <visual>
        <geometry>
          <mesh filename="package://kawasaki/meshes/rs005l/link_6_t.stl" scale="1000 1000 1000" />
        </geometry>
        <material name="blue"/>
      </visual>
      <collision>
        <geometry>
          <mesh filename="package://kawasaki/meshes/rs005l/link_6_t.stl" scale="1000 1000 1000" />
       </geometry>
      </collision>
    </link>
    <link name="${prefix}tool0"/>
    <!-- end of link list -->

    <!-- joint list -->
    <joint name="${prefix}joint_1_s" type="revolute">
      <parent link="${prefix}base_link"/>
      <child link="${prefix}link_1_s"/>
      <origin xyz="0 0 295" rpy="0 0 0" />
      <axis xyz="0 0 -1" />
      <limit lower="${radians(-180)}" upper="${radians(180)}" effort="1000.0" velocity="${radians(300)}"/>
    </joint>
    <joint name="${prefix}joint_2_l" type="revolute">
      <parent link="${prefix}link_1_s"/>
      <child link="${prefix}link_2_l"/>
      <origin xyz="0 105 0" rpy="0 0 0" />
      <axis xyz="-1 0 0" />
      <limit lower="${radians(-80)}" upper="${radians(135)}" effort="1000.0" velocity="${radians(300)}"/>
    </joint>
    <joint name="${prefix}joint_3_u" type="revolute">
      <parent link="${prefix}link_2_l"/>
      <child link="${prefix}link_3_u"/>
      <origin xyz="0 0 380" rpy="0 0 0" />
      <axis xyz="1 0 0" />
      <limit lower="${radians(-172)}" upper="${radians(118)}" effort="1000.0" velocity="${radians(300)}"/>
    </joint>
    <joint name="${prefix}joint_4_r" type="revolute">
      <parent link="${prefix}link_3_u"/>
      <child link="${prefix}link_4_r"/>
      <origin xyz="0 -80 410" rpy="0 0 0" />
      <axis xyz="0 0 1" />
      <limit lower="${radians(-360)}" upper="${radians(360)}" effort="1000.0" velocity="${radians(460)}"/>
    </joint>
    <joint name="${prefix}joint_5_b" type="revolute">
      <parent link="${prefix}link_4_r"/>
      <child link="${prefix}link_5_b"/>
      <origin xyz="0 0 0" rpy="0 0 0" />
      <axis xyz="1 0 0" />
      <limit lower="${radians(-145)}" upper="${radians(145)}" effort="1000.0" velocity="${radians(460)}"/>
    </joint>
    <joint name="${prefix}joint_6_t" type="revolute">
      <parent link="${prefix}link_5_b"/>
      <child link="${prefix}link_6_t"/>
      <origin xyz="0 0 78" rpy="0 0 0" />
      <axis xyz="0 0 1" />
      <limit lower="${radians(-360)}" upper="${radians(360)}" effort="1000.0" velocity="${radians(740)}"/>
    </joint>
    <joint name="${prefix}joint_6_t-tool0" type="fixed">
      <origin xyz="0 0 0" rpy="0 0 0"/>
      <parent link="${prefix}link_6_t"/>
      <child link="${prefix}tool0"/>
    </joint>
    <!-- end of joint list -->

    <!-- ROS base_link to Robot Manufacturer World Coordinates transform -->
    <link name="${prefix}base" />
    <joint name="${prefix}base_link-base" type="fixed">
      <origin xyz="0 0 0" rpy="0 0 0"/>
      <parent link="${prefix}base_link"/>
      <child link="${prefix}base"/>
    </joint>
  </xacro:macro>
</robot>
